[MFLOG|0|2025-04-16T23:28:21.972498Z|runtime|ec180127-f412-46b0-b5be-3522d4b3104c]<flow ScoringFlow step start> failed:
[MFLOG|0|2025-04-16T23:28:21.984111Z|runtime|c23cc7f9-1d8c-4453-ad9f-9494fddca531]    Internal error
[MFLOG|0|2025-04-16T23:28:21.984844Z|runtime|2b5cf408-db95-4e79-9bc8-404d71337519]Traceback (most recent call last):
[MFLOG|0|2025-04-16T23:28:21.984996Z|runtime|68d65353-9428-4800-b1de-d6751dbe9c8b]  File "/Users/chinguyen/Desktop/USF-MSDS/msds-603/mlops/src/scoringflow.py", line 18, in start
[MFLOG|0|2025-04-16T23:28:21.985051Z|runtime|24b6f382-973f-4536-8cd4-5e66ece0a07f]    self.model = mlflow.sklearn.load_model(self.model_uri)
[MFLOG|0|2025-04-16T23:28:21.985094Z|runtime|fc96bbc2-6844-451e-baeb-48777205cb7d]  File "/opt/homebrew/anaconda3/envs/mlops/lib/python3.10/site-packages/mlflow/sklearn/__init__.py", line 632, in load_model
[MFLOG|0|2025-04-16T23:28:21.985127Z|runtime|7a0b8d16-a7e4-4e06-b6c2-52ca3a44082c]    local_model_path = _download_artifact_from_uri(artifact_uri=model_uri, output_path=dst_path)
[MFLOG|0|2025-04-16T23:28:21.985165Z|runtime|d2a85100-d179-4179-afc1-b90c18eb4144]  File "/opt/homebrew/anaconda3/envs/mlops/lib/python3.10/site-packages/mlflow/tracking/artifact_utils.py", line 108, in _download_artifact_from_uri
[MFLOG|0|2025-04-16T23:28:21.985227Z|runtime|5787e3b9-12ba-4f9a-811d-a05b583f498c]    repo = get_artifact_repository(artifact_uri=root_uri)
[MFLOG|0|2025-04-16T23:28:21.985257Z|runtime|c730eb4c-0a1c-4332-a1dc-d205ab144455]  File "/opt/homebrew/anaconda3/envs/mlops/lib/python3.10/site-packages/mlflow/store/artifact/artifact_repository_registry.py", line 133, in get_artifact_repository
[MFLOG|0|2025-04-16T23:28:21.985294Z|runtime|15b94b9c-2b2c-40a5-a3ef-f266d5b7e7e2]    return _artifact_repository_registry.get_artifact_repository(artifact_uri)
[MFLOG|0|2025-04-16T23:28:21.985322Z|runtime|4aa20142-f861-467a-b199-746494327c34]  File "/opt/homebrew/anaconda3/envs/mlops/lib/python3.10/site-packages/mlflow/store/artifact/artifact_repository_registry.py", line 78, in get_artifact_repository
[MFLOG|0|2025-04-16T23:28:21.985424Z|runtime|d9a4f8a8-6fd3-4ff0-9e29-8962f1d2255b]    return repository(artifact_uri)
[MFLOG|0|2025-04-16T23:28:21.985476Z|runtime|ec4b3269-4f2c-46bc-a1a5-52e1b1f05207]  File "/opt/homebrew/anaconda3/envs/mlops/lib/python3.10/site-packages/mlflow/store/artifact/models_artifact_repo.py", line 59, in __init__
[MFLOG|0|2025-04-16T23:28:21.985513Z|runtime|78094075-2c96-4c21-9bbc-c487a429c474]    ) = ModelsArtifactRepository._get_model_uri_infos(artifact_uri)
[MFLOG|0|2025-04-16T23:28:21.985550Z|runtime|09db6ff5-fc05-4da5-9636-e4fb6b328076]  File "/opt/homebrew/anaconda3/envs/mlops/lib/python3.10/site-packages/mlflow/store/artifact/models_artifact_repo.py", line 93, in _get_model_uri_infos
[MFLOG|0|2025-04-16T23:28:21.985586Z|runtime|1fbaeefc-6353-42a9-9c4f-cee3e5cf2b20]    name, version = get_model_name_and_version(client, uri)
[MFLOG|0|2025-04-16T23:28:21.985621Z|runtime|a233ba61-5538-462a-b305-d81d398821f6]  File "/opt/homebrew/anaconda3/envs/mlops/lib/python3.10/site-packages/mlflow/store/artifact/utils/models.py", line 94, in get_model_name_and_version
[MFLOG|0|2025-04-16T23:28:21.985651Z|runtime|2f16ad71-9109-489c-aa20-198ca285b5a2]    return model_name, str(_get_latest_model_version(client, model_name, model_stage))
[MFLOG|0|2025-04-16T23:28:21.985681Z|runtime|b7fcc41e-a1c7-420d-8c31-a518e7314941]  File "/opt/homebrew/anaconda3/envs/mlops/lib/python3.10/site-packages/mlflow/store/artifact/utils/models.py", line 35, in _get_latest_model_version
[MFLOG|0|2025-04-16T23:28:21.985710Z|runtime|b113d511-dd7f-4f4c-b440-fce7f222b065]    raise MlflowException(f"No versions of model with name '{name}'{stage_str} found")
[MFLOG|0|2025-04-16T23:28:21.985739Z|runtime|10d84113-2faa-4da0-bf8d-61bfb47ddf75]mlflow.exceptions.MlflowException: No versions of model with name 'BestModel-MetaflowLab' and stage 'Production' found
[MFLOG|0|2025-04-16T23:28:21.985772Z|runtime|1943152b-0ad6-4c4c-bf1a-bc37a16e5c3d]
[MFLOG|0|2025-04-16T23:28:21.985802Z|runtime|a03cd3c8-c61b-4672-a59f-e13d3028a164]During handling of the above exception, another exception occurred:
[MFLOG|0|2025-04-16T23:28:21.985832Z|runtime|d75ed4a8-474c-4188-a525-3f86651f3439]
[MFLOG|0|2025-04-16T23:28:21.985861Z|runtime|3df82dbd-6fa9-4e6a-b7d5-bd19faff8083]Traceback (most recent call last):
[MFLOG|0|2025-04-16T23:28:21.985893Z|runtime|f0d7c989-3db5-4c31-b84b-52915e07e071]  File "/opt/homebrew/anaconda3/envs/mlops/lib/python3.10/site-packages/metaflow/cli.py", line 611, in main
[MFLOG|0|2025-04-16T23:28:21.985921Z|runtime|b262f914-bf47-4085-9d7a-deb7fdc2ea9e]    start(auto_envvar_prefix="METAFLOW", obj=state)
[MFLOG|0|2025-04-16T23:28:21.985949Z|runtime|ebb0520c-69c0-479e-9854-5557d3dec0ac]  File "/opt/homebrew/anaconda3/envs/mlops/lib/python3.10/site-packages/metaflow/_vendor/click/core.py", line 829, in __call__
[MFLOG|0|2025-04-16T23:28:21.985980Z|runtime|ebadedef-ccce-43d4-a95a-12adaed0af66]    return self.main(args, kwargs)
[MFLOG|0|2025-04-16T23:28:22.124312Z|runtime|362d79be-df51-493a-811c-2d82c1483035]  File "/opt/homebrew/anaconda3/envs/mlops/lib/python3.10/site-packages/metaflow/_vendor/click/core.py", line 782, in main
[MFLOG|0|2025-04-16T23:28:22.124504Z|runtime|d28f7e65-f1de-435d-9255-7f5caf5e9790]    rv = self.invoke(ctx)
[MFLOG|0|2025-04-16T23:28:22.124540Z|runtime|cb004601-6341-4002-afb2-6f3ef178a225]  File "/opt/homebrew/anaconda3/envs/mlops/lib/python3.10/site-packages/metaflow/cli_components/utils.py", line 69, in invoke
[MFLOG|0|2025-04-16T23:28:22.124570Z|runtime|97075cee-3ce2-4502-8d14-3259702f17da]    return _process_result(sub_ctx.command.invoke(sub_ctx))
[MFLOG|0|2025-04-16T23:28:22.124634Z|runtime|3ad0b10d-512b-493a-938e-94e20a63b8a1]  File "/opt/homebrew/anaconda3/envs/mlops/lib/python3.10/site-packages/metaflow/_vendor/click/core.py", line 1066, in invoke
[MFLOG|0|2025-04-16T23:28:22.124663Z|runtime|2724f312-b6aa-45f3-a280-9d1c9d770e45]    return ctx.invoke(self.callback, ctx.params)
[MFLOG|0|2025-04-16T23:28:22.124689Z|runtime|6d6a001d-2cbf-4201-bef6-a95d2de0893e]  File "/opt/homebrew/anaconda3/envs/mlops/lib/python3.10/site-packages/metaflow/_vendor/click/core.py", line 610, in invoke
[MFLOG|0|2025-04-16T23:28:22.124714Z|runtime|474c5e51-464e-41d5-bc91-99bcd6fd0531]    return callback(args, kwargs)
[MFLOG|0|2025-04-16T23:28:22.124740Z|runtime|80c812a9-9902-4b8b-bbc3-6f8e536cf272]  File "/opt/homebrew/anaconda3/envs/mlops/lib/python3.10/site-packages/metaflow/tracing/__init__.py", line 27, in wrapper_func
[MFLOG|0|2025-04-16T23:28:22.124764Z|runtime|9a481324-d723-42c6-90fd-3a43af07dcc0]    return func(args, kwargs)
[MFLOG|0|2025-04-16T23:28:22.124789Z|runtime|79acd345-1d38-48fd-a186-40a145f4ab26]  File "/opt/homebrew/anaconda3/envs/mlops/lib/python3.10/site-packages/metaflow/_vendor/click/decorators.py", line 21, in new_func
[MFLOG|0|2025-04-16T23:28:22.124813Z|runtime|6e8539dc-e81c-44ef-9263-ae0d980f3158]    return f(get_current_context(), args, kwargs)
[MFLOG|0|2025-04-16T23:28:22.124838Z|runtime|982eaebd-1109-49c2-ba7e-33bfc6bfd8b1]  File "/opt/homebrew/anaconda3/envs/mlops/lib/python3.10/site-packages/metaflow/cli_components/step_cmd.py", line 167, in step
[MFLOG|0|2025-04-16T23:28:22.124862Z|runtime|6566390e-f522-4765-aa5c-5d5ea0771b98]    task.run_step(
[MFLOG|0|2025-04-16T23:28:22.124887Z|runtime|95ad7d7e-6287-4c5e-9e0c-733837b85be4]  File "/opt/homebrew/anaconda3/envs/mlops/lib/python3.10/site-packages/metaflow/task.py", line 672, in run_step
[MFLOG|0|2025-04-16T23:28:22.124912Z|runtime|81891a7c-4d93-4858-bfbd-8451fafb74a1]    self._exec_step_function(step_func)
[MFLOG|0|2025-04-16T23:28:22.124936Z|runtime|7b5581e2-8252-48c8-a0dc-1680ee769a9c]  File "/opt/homebrew/anaconda3/envs/mlops/lib/python3.10/site-packages/metaflow/task.py", line 62, in _exec_step_function
[MFLOG|0|2025-04-16T23:28:22.124961Z|runtime|e26788e6-78cb-4780-a115-5a88b5c7bc81]    step_function()
[MFLOG|0|2025-04-16T23:28:22.124988Z|runtime|ba4a16da-1cf8-44df-b5cc-be4c552ea723]  File "/Users/chinguyen/Desktop/USF-MSDS/msds-603/mlops/src/scoringflow.py", line 20, in start
[MFLOG|0|2025-04-16T23:28:22.125046Z|runtime|02e55df7-349a-4914-b32d-91f9626dbad7]    raise RuntimeError(f"Failed to load model from {self.model_uri}\nError: {e}")
[MFLOG|0|2025-04-16T23:28:22.125076Z|runtime|1f4dfce1-01b6-4277-ad38-646068ddc5c2]RuntimeError: Failed to load model from models:/BestModel-MetaflowLab/Production
[MFLOG|0|2025-04-16T23:28:22.125102Z|runtime|a8eb3534-37fe-4eef-bb0c-8de1536e36e9]Error: No versions of model with name 'BestModel-MetaflowLab' and stage 'Production' found
[MFLOG|0|2025-04-16T23:28:22.125167Z|runtime|3620e1d8-8f44-462b-830f-2b1324b6aa90]
[MFLOG|0|2025-04-16T23:28:22.125643Z|runtime|952346d3-e993-4386-95d4-7bb4146bd532]Task failed.