[MFLOG|0|2025-04-16T23:28:33.480809Z|runtime|f2e2b908-2100-4cdc-8eaf-a3c9699348a1]<flow ScoringFlow step predict> failed:
[MFLOG|0|2025-04-16T23:28:33.489095Z|runtime|64dc1ef7-5c86-4192-a5d0-bedd8eb3dec0]    Internal error
[MFLOG|0|2025-04-16T23:28:33.490015Z|runtime|e9bc21a9-7f20-47ba-80ef-ff7aa0d7e40c]Traceback (most recent call last):
[MFLOG|0|2025-04-16T23:28:33.490158Z|runtime|4f23f706-5c80-4d0b-b7fe-7c28f4ce8b45]  File "/Users/chinguyen/Desktop/USF-MSDS/msds-603/mlops/src/scoringflow.py", line 27, in predict
[MFLOG|0|2025-04-16T23:28:33.490248Z|runtime|c082471d-a197-4794-a24d-a2844cee3de4]    self.prediction = self.model.predict([self.vector])[0]
[MFLOG|0|2025-04-16T23:28:33.490291Z|runtime|b6834548-4405-4d92-979d-3af0a02a7635]  File "/opt/homebrew/anaconda3/envs/mlops/lib/python3.10/site-packages/sklearn/ensemble/_forest.py", line 904, in predict
[MFLOG|0|2025-04-16T23:28:33.490380Z|runtime|37ff9295-92b9-45d0-a4da-e9dd2739c030]    proba = self.predict_proba(X)
[MFLOG|0|2025-04-16T23:28:33.490461Z|runtime|9d5b4489-1650-48a3-b37a-85cf55b09897]  File "/opt/homebrew/anaconda3/envs/mlops/lib/python3.10/site-packages/sklearn/ensemble/_forest.py", line 946, in predict_proba
[MFLOG|0|2025-04-16T23:28:33.490523Z|runtime|936ec3db-71f2-44a3-9713-e44a93121872]    X = self._validate_X_predict(X)
[MFLOG|0|2025-04-16T23:28:33.490557Z|runtime|a2b7056f-cefe-484b-abc4-837401ddec17]  File "/opt/homebrew/anaconda3/envs/mlops/lib/python3.10/site-packages/sklearn/ensemble/_forest.py", line 641, in _validate_X_predict
[MFLOG|0|2025-04-16T23:28:33.490588Z|runtime|c68245d4-b0bc-4fe4-b258-a315aa0991bd]    X = self._validate_data(
[MFLOG|0|2025-04-16T23:28:33.490621Z|runtime|845e3828-bf81-4bce-bc8d-12b1e2b09610]  File "/opt/homebrew/anaconda3/envs/mlops/lib/python3.10/site-packages/sklearn/base.py", line 654, in _validate_data
[MFLOG|0|2025-04-16T23:28:33.490652Z|runtime|8927a91d-00d2-4549-8d23-5ff404ece7c9]    self._check_n_features(X, reset=reset)
[MFLOG|0|2025-04-16T23:28:33.490682Z|runtime|7fea6297-c3af-464d-96b9-2e164a6ac7d3]  File "/opt/homebrew/anaconda3/envs/mlops/lib/python3.10/site-packages/sklearn/base.py", line 443, in _check_n_features
[MFLOG|0|2025-04-16T23:28:33.490710Z|runtime|7e461dea-10de-4990-a5de-f73692f5782a]    raise ValueError(
[MFLOG|0|2025-04-16T23:28:33.490746Z|runtime|34dc89ab-9881-4d5b-81e3-c557429572dd]ValueError: X has 13 features, but RandomForestClassifier is expecting 6 features as input.
[MFLOG|0|2025-04-16T23:28:33.490794Z|runtime|6cc3565d-2afc-4b41-bfe3-3367c62656bb]
[MFLOG|0|2025-04-16T23:28:33.490827Z|runtime|5ff61fd1-e554-4fe6-a3d0-95807d6c7eaa]During handling of the above exception, another exception occurred:
[MFLOG|0|2025-04-16T23:28:33.490857Z|runtime|27f3f389-6c22-4d70-83cf-59871b695248]
[MFLOG|0|2025-04-16T23:28:33.490886Z|runtime|95e4e479-05eb-4fa0-b251-2e02182a591d]Traceback (most recent call last):
[MFLOG|0|2025-04-16T23:28:33.490915Z|runtime|3dfb0572-bdd3-4913-969b-5ff65bf5c756]  File "/opt/homebrew/anaconda3/envs/mlops/lib/python3.10/site-packages/metaflow/cli.py", line 611, in main
[MFLOG|0|2025-04-16T23:28:33.490946Z|runtime|5d7453a2-7ef6-4927-8f09-7cc393251794]    start(auto_envvar_prefix="METAFLOW", obj=state)
[MFLOG|0|2025-04-16T23:28:33.490976Z|runtime|d3c7e542-8f6a-4cd3-9ae6-07891c3b9c01]  File "/opt/homebrew/anaconda3/envs/mlops/lib/python3.10/site-packages/metaflow/_vendor/click/core.py", line 829, in __call__
[MFLOG|0|2025-04-16T23:28:33.491009Z|runtime|88af587a-a9e9-4b3e-afe7-52caf747557d]    return self.main(args, kwargs)
[MFLOG|0|2025-04-16T23:28:33.655262Z|runtime|7583e0cd-6ee3-400c-b30a-de1b622b22e1]  File "/opt/homebrew/anaconda3/envs/mlops/lib/python3.10/site-packages/metaflow/_vendor/click/core.py", line 782, in main
[MFLOG|0|2025-04-16T23:28:33.655444Z|runtime|df5857a9-4f24-40f8-acde-d465849281e9]    rv = self.invoke(ctx)
[MFLOG|0|2025-04-16T23:28:33.655483Z|runtime|1e97d2e3-0452-40b3-99a4-751da63ce470]  File "/opt/homebrew/anaconda3/envs/mlops/lib/python3.10/site-packages/metaflow/cli_components/utils.py", line 69, in invoke
[MFLOG|0|2025-04-16T23:28:33.655514Z|runtime|87e55bd0-4940-46d0-baa4-35b86c8a901a]    return _process_result(sub_ctx.command.invoke(sub_ctx))
[MFLOG|0|2025-04-16T23:28:33.655543Z|runtime|1392d647-93b7-4e6d-8796-d375c146b24b]  File "/opt/homebrew/anaconda3/envs/mlops/lib/python3.10/site-packages/metaflow/_vendor/click/core.py", line 1066, in invoke
[MFLOG|0|2025-04-16T23:28:33.655567Z|runtime|fd93ab6f-ba76-4304-9087-07322c68a6df]    return ctx.invoke(self.callback, ctx.params)
[MFLOG|0|2025-04-16T23:28:33.655594Z|runtime|055c977b-2f83-4d6a-82cf-f4385d241add]  File "/opt/homebrew/anaconda3/envs/mlops/lib/python3.10/site-packages/metaflow/_vendor/click/core.py", line 610, in invoke
[MFLOG|0|2025-04-16T23:28:33.655619Z|runtime|1901ec05-1b10-4f7e-935e-808601af2a69]    return callback(args, kwargs)
[MFLOG|0|2025-04-16T23:28:33.655645Z|runtime|d690209c-3f90-4566-8434-4776c860eb46]  File "/opt/homebrew/anaconda3/envs/mlops/lib/python3.10/site-packages/metaflow/tracing/__init__.py", line 27, in wrapper_func
[MFLOG|0|2025-04-16T23:28:33.655670Z|runtime|039884c1-4334-4744-b0f1-515844d40a9c]    return func(args, kwargs)
[MFLOG|0|2025-04-16T23:28:33.655698Z|runtime|7ae79684-63c7-4298-9c6a-66767d1fc8bd]  File "/opt/homebrew/anaconda3/envs/mlops/lib/python3.10/site-packages/metaflow/_vendor/click/decorators.py", line 21, in new_func
[MFLOG|0|2025-04-16T23:28:33.655725Z|runtime|66591546-3aac-4095-981b-03303973922b]    return f(get_current_context(), args, kwargs)
[MFLOG|0|2025-04-16T23:28:33.655749Z|runtime|3c95c1b8-0d67-4589-87bc-acd6cb300ebf]  File "/opt/homebrew/anaconda3/envs/mlops/lib/python3.10/site-packages/metaflow/cli_components/step_cmd.py", line 167, in step
[MFLOG|0|2025-04-16T23:28:33.655773Z|runtime|9d0e3875-b49f-42a2-a17c-ac46fe4b1131]    task.run_step(
[MFLOG|0|2025-04-16T23:28:33.655802Z|runtime|878507e3-243c-4241-afca-333ec598bea8]  File "/opt/homebrew/anaconda3/envs/mlops/lib/python3.10/site-packages/metaflow/task.py", line 672, in run_step
[MFLOG|0|2025-04-16T23:28:33.655827Z|runtime|880a5061-66b6-418f-b1dc-805361e54fff]    self._exec_step_function(step_func)
[MFLOG|0|2025-04-16T23:28:33.655854Z|runtime|9db9bfa9-107c-4ec8-a03a-c5fe122d1aca]  File "/opt/homebrew/anaconda3/envs/mlops/lib/python3.10/site-packages/metaflow/task.py", line 62, in _exec_step_function
[MFLOG|0|2025-04-16T23:28:33.655878Z|runtime|d15bf469-9be5-4bc5-8c6f-687ccb0dcca9]    step_function()
[MFLOG|0|2025-04-16T23:28:33.655931Z|runtime|f856aced-3cb0-459c-987d-219017913456]  File "/Users/chinguyen/Desktop/USF-MSDS/msds-603/mlops/src/scoringflow.py", line 31, in predict
[MFLOG|0|2025-04-16T23:28:33.655956Z|runtime|3841d90e-8046-4af7-81a8-2cc980ab9070]    raise RuntimeError(f"Prediction failed: {e}")
[MFLOG|0|2025-04-16T23:28:33.655988Z|runtime|eda40766-bfbd-49b4-8fcf-f8db4d55f3fe]RuntimeError: Prediction failed: X has 13 features, but RandomForestClassifier is expecting 6 features as input.
[MFLOG|0|2025-04-16T23:28:33.656012Z|runtime|89d83552-9372-411b-9eb3-a94e22eefa76]
[MFLOG|0|2025-04-16T23:28:33.656388Z|runtime|d73c3238-95fe-4c95-8b17-b7123a6c4b26]Task failed.